Workbook

Sheet Leia-me
B2: Ficha técnica do Maluzices
B3: Esta planilha já vem preenchida com as suas receitas. É para conferir e, daqui para frente, manter.
B5: Como ler as cores
B6: Fundo amarelo e letra azul: campo seu, pode digitar à vontade.
B7: Letra preta: a planilha calcula sozinha. Se você digitar por cima, a conta some.
B8: Letra verde: o valor vem de outra aba.
B9: Linhas de fundo claro no topo dos Insumos: sub-receitas, com preço calculado.
B11: As abas
B12: Insumos: tudo que você compra, com peso bruto, peso líquido e preço.
B13: Produtos: uma linha por receita, com rendimento, preço e os custos calculados.
B14: Ingredientes: o que entra em cada receita e quanto. É daqui que sai o custo.
B15: Conferência: compara estes números com os da sua planilha antiga.
... B44: Alguns ingredientes continuam sem preço porque não existem na lista de insumos com nenhum nome parecido (óleo de girassol, melado de cana, gelo, entre outros). Eles estão listados na aba Pendências. Enquanto não tiverem preço, as receitas que os usam continuam saindo mais baratas do que são.

Sheet Insumos
A1: Insumos
A2: Tudo que entra nas receitas. As linhas amarelas são as que você preenche; as de fundo claro no topo são sub-receitas e têm o preço calculado sozinho.
A3: Código | B3: Nome | C3: Unidade | D3: Peso bruto | E3: Peso líquido | F3: Fator de correção | G3: Preço por quilo | H3: Fornecedor | I3: Data da cotação | J3: Observação
A4: creme-de-castanha | B4: Creme de Castanha | C4: kg | D4: 1 | E4: 1 | F4: =IFERROR(E4/D4,1) -> 1 | G4: =Produtos!$M$17 -> 27.661974 | H4: cozinha | J4: Sub-receita: o preço sai da aba Produtos, não se digita.
A5: creme-para-quiche | B5: Creme para Quiche | C5: kg | D5: 0.5 | E5: 0.5 | F5: =IFERROR(E5/D5,1) -> 1 | G5: =Produtos!$M$40 -> 14.666824 | H5: cozinha | J5: Sub-receita: o preço sai da aba Produtos, não se digita.
A6: frango-desfiado | B6: Frango Desfiado | C6: kg | D6: 1 | E6: 0.5 | F6: =IFERROR(E6/D6,1) -> 0.5 | G6: =Produtos!$M$28 -> 22.902943 | H6: cozinha | J6: Sub-receita: o preço sai da aba Produtos, não se digita.
A7: frango-desfiado-com-molho-de-tomate | B7: Frango Desfiado com Molho de Tomate | C7: kg | D7: 1 | E7: 1 | F7: =IFERROR(E7/D7,1) -> 1 | G7: =Produtos!$M$29 -> 34.885912 | H7: cozinha | J7: Sub-receita: o preço sai da aba Produtos, não se digita.
A8: leite-de-amendoim | B8: Leite de Amendoim | C8: L | D8: 1 | E8: 0.98 | F8: =IFERROR(E8/D8,1) -> 0.98 | G8: =Produtos!$M$33 -> 3.0612245 | H8: cozinha | J8: Sub-receita: o preço sai da aba Produtos, não se digita.
A9: leite-de-arroz | B9: Leite de Arroz | C9: L | D9: 1 | E9: 0.98 | F9: =IFERROR(E9/D9,1) -> 0.98 | G9: =Produtos!$M$34 -> 1.5306122 | H9: cozinha | J9: Sub-receita: o preço sai da aba Produtos, não se digita.
A10: maionese-verde | B10: Maionese Verde | C10: kg | D10: 1 | E10: 1.134 | F10: =IFERROR(E10/D10,1) -> 1.134 | G10: =Produtos!$M$35 -> 6.0598778 | H10: cozinha | J10: Sub-receita: o preço sai da aba Produtos, não se digita.
A11: manteiga-vegana | B11: Manteiga Vegana | C11: kg | D11: 0.8 | E11: 0.8 | F11: =IFERROR(E11/D11,1) -> 1 | G11: =Produtos!$M$37 -> 25.283136 | H11: cozinha | J11: Sub-receita: o preço sai da aba Produtos, não se digita.
A12: massa-low-carb-para-quiche | B12: Massa Low Carb para Quiche | C12: kg | D12: 1 | E12: 1 | F12: =IFERROR(E12/D12,1) -> 1 | G12: =Produtos!$M$39 -> 14.050145 | H12: cozinha | J12: Sub-receita: o preço sai da aba Produtos, não se digita.
A13: massa-de-esfira | B13: Massa de Esfira | C13: kg | D13: 1 | E13: 1 | F13: =IFERROR(E13/D13,1) -> 1 | G13: =Produtos!$M$43 -> 13.987941 | H13: cozinha | J13: Sub-receita: o preço sai da aba Produtos, não se digita.
A14: mix-de-sementes-para-pao | B14: Mix de Sementes para Pão | C14: kg | D14: 1 | E14: 1 | F14: =IFERROR(E14/D14,1) -> 1 | G14: =Produtos!$M$45 -> 45.921939 | H14: cozinha | J14: Sub-receita: o preço sai da aba Produtos, não se digita.
A15: mix-sem-gluten-cris-gutierrez | B15: Mix sem Glúten Cris Gutierrez | C15: kg | D15: 1 | E15: 0.98 | F15: =IFERROR(E15/D15,1) -> 0.98 | G15: =Produtos!$M$47 -> 10.219598 | H15: cozinha | J15: Sub-receita: o preço sai da aba Produtos, não se digita.
A16: pure-de-batatas | B16: Purê de Batatas | C16: kg | D16: 1 | E16: 1 | F16: =IFERROR(E16/D16,1) -> 1 | G16: =Produtos!$M$54 -> 12.142728 | H16: cozinha | J16: Sub-receita: o preço sai da aba Produtos, não se digita.
A17: pao-roberta | B17: Pão Roberta | C17: kg | D17: 1 | E17: 0.98 | F17: =IFERROR(E17/D17,1) -> 0.98 | G17: =Produtos!$M$56 -> 9.3401927 | H17: cozinha | J17: Sub-receita: o preço sai da aba Produtos, não se digita.
A18: pao-nobis | B18: Pão-nóbis | C18: kg | D18: 1 | E18: 1 | F18: =IFERROR(E18/D18,1) -> 1 | G18: =Produtos!$M$64 -> 11.85252 | H18: cozinha | J18: Sub-receita: o preço sai da aba Produtos, não se digita.
A19: requeiju | B19: Requeiju | C19: kg | D19: 1 | E19: 1.18 | F19: =IFERROR(E19/D19,1) -> 1.18 | G19: =Produtos!$M$70 -> 16.769479 | H19: cozinha | J19: Sub-receita: o preço sai da aba Produtos, não se digita.
A20: abacaxi-sem-casca | B20: Abacaxi sem Casca | C20: kg | D20: 1 | E20: 0.63 | F20: =IFERROR(E20/D20,1) -> 0.63 | G20: 4 | H20: Cantina
A21: abobora-cabotia | B21: Abobora Cabotia | C21: kg | D21: 1 | E21: 0.97 | F21: =IFERROR(E21/D21,1) -> 0.97 | G21: 6
A22: abobrinha-crua | B22: Abobrinha Crua | C22: kg | D22: 1 | E22: 0.95 | F22: =IFERROR(E22/D22,1) -> 0.95 | G22: 2.49
A23: alecrim | B23: Alecrim | C23: kg | D23: 1 | E23: 0.95 | F23: =IFERROR(E23/D23,1) -> 0.95 | G23: 10
A24: alface | B24: Alface | C24: kg | D24: 1 | E24: 0.79 | F24: =IFERROR(E24/D24,1) -> 0.79 | G24: 5
A25: alho-cru | B25: Alho Cru | C25: kg | D25: 1 | E25: 0.88 | F25: =IFERROR(E25/D25,1) -> 0.88 | G25: 24.99
A26: alho-descascado | B26: Alho Descascado | C26: kg | D26: 1 | E26: 0.88 | F26: =IFERROR(E26/D26,1) -> 0.88 | G26: 20
A27: alho-poro | B27: Alho-poró | C27: kg | D27: 1 | E27: 0.9 | F27: =IFERROR(E27/D27,1) -> 0.9 | G27: 50 | H27: Feirinha
A28: amaranto-em-flocos | B28: Amaranto em Flocos | C28: kg | D28: 1 | E28: 0.98 | F28: =IFERROR(E28/D28,1) -> 0.98 | G28: 23 | H28: Ares
A29: amendoas-em-castanha | B29: Amendoas em Castanha | C29: kg | D29: 1 | E29: 0.9 | F29: =IFERROR(E29/D29,1) -> 0.9 | G29: 62 | H29: Ares
A30: amendoim | B30: Amendoim | C30: kg | D30: 1 | E30: 0.98 | F30: =IFERROR(E30/D30,1) -> 0.98 | G30: 5.3 | H30: Cedro
A31: amido-de-milho | B31: Amido de Milho | C31: kg | D31: 0.5 | E31: 0.49 | F31: =IFERROR(E31/D31,1) -> 0.98 | G31: 4
A32: aveia | B32: Aveia | C32: kg | D32: 1 | E32: 0.98 | F32: =IFERROR(E32/D32,1) -> 0.98 | G32: 16.9
A33: aveia-em-flocos-grossos | B33: Aveia em Flocos Grossos | C33: kg | D33: 1 | E33: 0.98 | F33: =IFERROR(E33/D33,1) -> 0.98 | G33: 18.26
A34: avela-torrada | B34: Avelã Torrada | C34: kg | D34: 1 | E34: 0.88 | F34: =IFERROR(E34/D34,1) -> 0.88 | G34: 90 | H34: Ares da Natureza
A35: azeite-de-oliva | B35: Azeite de Oliva | C35: kg | D35: 1 | E35: 0.95 | F35: =IFERROR(E35/D35,1) -> 0.95 | G35: 20 | H35: Argentina
A36: acucar-demerara | B36: Açucar Demerara | C36: kg | D36: 1 | E36: 0.98 | F36: =IFERROR(E36/D36,1) -> 0.98 | G36: 6 | H36: Cedro
A37: acucar-mascavo | B37: Açúcar Mascavo | C37: kg | D37: 1 | E37: 0.98 | F37: =IFERROR(E37/D37,1) -> 0.98 | G37: 9 | H37: Equi
A38: acucar-de-coco | B38: Açúcar de Coco | C38: kg | D38: 1 | E38: 0.97 | F38: =IFERROR(E38/D38,1) -> 0.97 | G38: 26.2 | H38: Ares
A39: banana-com-casca | B39: Banana com Casca | C39: kg | D39: 1 | E39: 0.95 | F39: =IFERROR(E39/D39,1) -> 0.95 | G39: 6
A40: banana-sem-casca | B40: Banana sem Casca | C40: kg | D40: 1 | E40: 0.62 | F40: =IFERROR(E40/D40,1) -> 0.62 | G40: 10 | H40: Cantina da Fruta
...

Sheet Produtos
A1: Produtos e receitas
A2: Um por linha. Os 12 primeiros são os que você vende; os de baixo são bases e sub-receitas que entram em outras fichas.
A3: Código | B3: Nome | C3: Categoria | D3: Rendimento (porções) | E3: Rendimento (kg) | F3: Tempo de preparo | G3: Vende? | H3: Preço praticado | I3: Meta de CMV | J3: Custo da receita | K3: Custo por porção | L3: Preço sugerido | M3: Custo por quilo | N3: CMV real | O3: Custo na planilha antiga | P3: Diferença
A4: caldo-de-batata-doce | B4: Caldo de Batata Doce | C4: Caldos | D4: 9 | F4: 10 min | G4: Sim | H4: 18 | I4: 0.3 | J4: =SUM(Ingredientes!$I$4:$I$10) -> 48.493647 | K4: =IFERROR(J4/D4,0) -> 5.388183 | L4: =IFERROR(K4/I4,0) -> 17.96061 | M4: =IFERROR(J4/IF(E4>0,E4,SUM(Ingredientes!$E$4:$E$10)),0) -> 13.895028 | N4: =IFERROR(K4/H4,0) -> 0.2993435 | O4: 5.3232 | P4: =IFERROR(K4-O4,0) -> 0.06498298
A5: caldo-de-cabotia | B5: Caldo de Cabotia | C5: Caldos | D5: 9 | F5: 10 min | G5: Sim | H5: 18 | I5: 0.3 | J5: =SUM(Ingredientes!$I$11:$I$17) -> 48.073902 | K5: =IFERROR(J5/D5,0) -> 5.3415447 | L5: =IFERROR(K5/I5,0) -> 17.805149 | M5: =IFERROR(J5/IF(E5>0,E5,SUM(Ingredientes!$E$11:$E$17)),0) -> 13.774757 | N5: =IFERROR(K5/H5,0) -> 0.29675248 | O5: 5.2765 | P5: =IFERROR(K5-O5,0) -> 0.065044711
A6: caldo-de-legumes-e-frango | B6: Caldo de Legumes e Frango | C6: Caldos | D6: 9 | F6: 10 min | G6: Sim | H6: 18 | I6: 0.34 | J6: =SUM(Ingredientes!$I$18:$I$27) -> 55.515484 | K6: =IFERROR(J6/D6,0) -> 6.1683871 | L6: =IFERROR(K6/I6,0) -> 18.142315 | M6: =IFERROR(J6/IF(E6>0,E6,SUM(Ingredientes!$E$18:$E$27)),0) -> 15.907015 | N6: =IFERROR(K6/H6,0) -> 0.34268817 | O6: 6.1034 | P6: =IFERROR(K6-O6,0) -> 0.064987069
A7: coxinha-de-batata-doce | B7: Coxinha Massa Trad | C7: Salgados fritos | D7: 19 | F7: 1H | G7: Sim | H7: 20 | I7: 0.17 | J7: =SUM(Ingredientes!$I$28:$I$32) -> 68.587563 | K7: =IFERROR(J7/D7,0) -> 3.6098718 | L7: =IFERROR(K7/I7,0) -> 21.23454 | M7: =IFERROR(J7/IF(E7>0,E7,SUM(Ingredientes!$E$28:$E$32)),0) -> 19.380493 | N7: =IFERROR(K7/H7,0) -> 0.18049359 | O7: 3.5749 | P7: =IFERROR(K7-O7,0) -> 0.034971762
A8: cracker-sem-gluten | B8: Cracker sem Glúten | C8: Salgados assados | D8: 3 | F8: 1H | G8: Sim | H8: 12 | I8: 0.2 | J8: =SUM(Ingredientes!$I$33:$I$45) -> 7.3380005 | K8: =IFERROR(J8/D8,0) -> 2.4460002 | L8: =IFERROR(K8/I8,0) -> 12.230001 | M8: =IFERROR(J8/IF(E8>0,E8,SUM(Ingredientes!$E$33:$E$45)),0) -> 14.690692 | N8: =IFERROR(K8/H8,0) -> 0.20383335 | O8: 2.446 | P8: =IFERROR(K8-O8,0) -> 1.7901898e-07
A9: esfira-de-carne | B9: Esfira de Carne | C9: Salgados assados | D9: 15 | F9: 10 min | G9: Sim | H9: 18 | I9: 0.35 | J9: =SUM(Ingredientes!$I$46:$I$47) -> 91.0236 | K9: =IFERROR(J9/D9,0) -> 6.06824 | L9: =IFERROR(K9/I9,0) -> 17.337829 | M9: =IFERROR(J9/IF(E9>0,E9,SUM(Ingredientes!$E$46:$E$47)),0) -> 35.556094 | N9: =IFERROR(K9/H9,0) -> 0.33712444 | O9: 6.1932 | P9: =IFERROR(K9-O9,0) -> -0.12496
A10: massa-mini-pizza | B10: Massa Mini Pizza | C10: Massas e bases | D10: 9 | F10: 1H | G10: Sim | H10: 3 | I10: 0.2 | J10: =SUM(Ingredientes!$I$48:$I$56) -> 5.3233049 | K10: =IFERROR(J10/D10,0) -> 0.59147832 | L10: =IFERROR(K10/I10,0) -> 2.9573916 | M10: =IFERROR(J10/IF(E10>0,E10,SUM(Ingredientes!$E$48:$E$56)),0) -> 13.476721 | N10: =IFERROR(K10/H10,0) -> 0.19715944 | O10: 0.5915 | P10: =IFERROR(K10-O10,0) -> -2.1679198e-05
A11: pao-de-mandioquinha | B11: Pão de Mandioquinha | C11: Pães | D11: 16 | F11: 2HR | G11: Sim | H11: 12 | I11: 0.17 | J11: =SUM(Ingredientes!$I$57:$I$64) -> 30.993036 | K11: =IFERROR(J11/D11,0) -> 1.9370648 | L11: =IFERROR(K11/I11,0) -> 11.394499 | M11: =IFERROR(J11/IF(E11>0,E11,SUM(Ingredientes!$E$57:$E$64)),0) -> 12.738609 | N11: =IFERROR(K11/H11,0) -> 0.16142206 | O11: 1.9371 | P11: =IFERROR(K11-O11,0) -> -3.5239885e-05
A12: quiche-de-brocolis | B12: Quiche de Brócolis | C12: Salgados assados | D12: 10 | F12: 10 min | G12: Sim | H12: 17 | I12: 0.24 | J12: =SUM(Ingredientes!$I$65:$I$68) -> 40.620223 | K12: =IFERROR(J12/D12,0) -> 4.0620223 | L12: =IFERROR(K12/I12,0) -> 16.925093 | M12: =IFERROR(J12/IF(E12>0,E12,SUM(Ingredientes!$E$65:$E$68)),0) -> 25.38764 | N12: =IFERROR(K12/H12,0) -> 0.23894249 | O12: 3.9601 | P12: =IFERROR(K12-O12,0) -> 0.10192233
A13: quiche-de-frango | B13: Quiche de Frango | C13: Salgados assados | D13: 10 | F13: 10 min | G13: Sim | H13: 17 | I13: 0.24 | J13: =SUM(Ingredientes!$I$69:$I$72) -> 39.214652 | K13: =IFERROR(J13/D13,0) -> 3.9214652 | L13: =IFERROR(K13/I13,0) -> 16.339438 | M13: =IFERROR(J13/IF(E13>0,E13,SUM(Ingredientes!$E$69:$E$72)),0) -> 24.509157 | N13: =IFERROR(K13/H13,0) -> 0.23067442 | O13: 3.923 | P13: =IFERROR(K13-O13,0) -> -0.0015348205
A14: sanduba-de-frango | B14: Sanduba de Pao-nobis, Frango e Requeiju | C14: Pães | D14: 1 | F14: MODO DE PREPARO | G14: Sim | H14: 17 | I14: 0.2 | J14: =SUM(Ingredientes!$I$73:$I$77) -> 3.3499976 | K14: =IFERROR(J14/D14,0) -> 3.3499976 | L14: =IFERROR(K14/I14,0) -> 16.749988 | M14: =IFERROR(J14/IF(E14>0,E14,SUM(Ingredientes!$E$73:$E$77)),0) -> 3.0593585 | N14: =IFERROR(K14/H14,0) -> 0.19705868 | O14: 3.3114 | P14: =IFERROR(K14-O14,0) -> 0.038597595
A15: torta-salgada-de-frango | B15: Torta Salgada de Frango | C15: Salgados assados | D15: 7 | F15: 40 min | G15: Sim | H15: 15 | I15: 0.2 | J15: =SUM(Ingredientes!$I$78:$I$85) -> 20.486057 | K15: =IFERROR(J15/D15,0) -> 2.9265796 | L15: =IFERROR(K15/I15,0) -> 14.632898 | M15: =IFERROR(J15/IF(E15>0,E15,SUM(Ingredientes!$E$78:$E$85)),0) -> 19.698132 | N15: =IFERROR(K15/H15,0) -> 0.19510531 | O15: 2.8823 | P15: =IFERROR(K15-O15,0) -> 0.044279608
A16: batida-nuts | B16: Batida de Nuts | C16: Bebidas | D16: 1 | F16: 5 min | G16: Não | J16: =SUM(Ingredientes!$I$86:$I$90) -> 2.3583114 | K16: =IFERROR(J16/D16,0) -> 2.3583114 | L16: =IFERROR(K16/I16,0) -> 0 | M16: =IFERROR(J16/IF(E16>0,E16,SUM(Ingredientes!$E$86:$E$90)),0) -> 10.435006 | N16: =IFERROR(K16/H16,0) -> 0 | O16: 2.3583 | P16: =IFERROR(K16-O16,0) -> 1.1389072e-05
A17: creme-de-castanha | B17: Catupiry de Castanha | C17: Caldos | D17: 1 | E17: 0.6217 | F17: 10 min | G17: Não | J17: =SUM(Ingredientes!$I$91:$I$94) -> 17.197449 | K17: =IFERROR(J17/D17,0) -> 17.197449 | L17: =IFERROR(K17/I17,0) -> 0 | M17: =IFERROR(J17/IF(E17>0,E17,SUM(Ingredientes!$E$91:$E$94)),0) -> 27.661974 | N17: =IFERROR(K17/H17,0) -> 0 | O17: 17.1974 | P17: =IFERROR(K17-O17,0) -> 4.8979592e-05
A18: coxinha-de-festa | B18: Coxinha de Festa | C18: Salgados fritos | D18: 25 | F18: 40 min | G18: Não | J18: =SUM(Ingredientes!$I$95:$I$99) -> 9.5413412 | K18: =IFERROR(J18/D18,0) -> 0.38165365 | L18: =IFERROR(K18/I18,0) -> 0 | M18: =IFERROR(J18/IF(E18>0,E18,SUM(Ingredientes!$E$95:$E$99)),0) -> 11.495592 | N18: =IFERROR(K18/H18,0) -> 0 | O18: 0.3827 | P18: =IFERROR(K18-O18,0) -> -0.0010463523
A19: croquete-de-batata-e-frango | B19: Croquete de Batata e Frango | C19: Salgados fritos | D19: 10 | F19: 1H | G19: Não | J19: =SUM(Ingredientes!$I$100:$I$107) -> 31.517018 | K19: =IFERROR(J19/D19,0) -> 3.1517018 | L19: =IFERROR(K19/I19,0) -> 0 | M19: =IFERROR(J19/IF(E19>0,E19,SUM(Ingredientes!$E$100:$E$107)),0) -> 21.947784 | N19: =IFERROR(K19/H19,0) -> 0 | O19: 3.0867 | P19: =IFERROR(K19-O19,0) -> 0.065001816
A20: croquete-de-carne-e-cabotia | B20: Croquete de Batata e Frango | C20: Salgados fritos | D20: 47 | F20: 1H | G20: Não | J20: =SUM(Ingredientes!$I$108:$I$117) -> 45.86076 | K20: =IFERROR(J20/D20,0) -> 0.97576086 | L20: =IFERROR(K20/I20,0) -> 0 | M20: =IFERROR(J20/IF(E20>0,E20,SUM(Ingredientes!$E$108:$E$117)),0) -> 35.386389 | N20: =IFERROR(K20/H20,0) -> 0 | O20: 0.9758 | P20: =IFERROR(K20-O20,0) -> -3.9143761e-05
A21: empada-de-frango | B21: Empada de Frango | C21: Salgados assados | D21: 1 | F21: 10 min | G21: Não | J21: =SUM(Ingredientes!$I$118:$I$119) -> 1.9486759 | K21: =IFERROR(J21/D21,0) -> 1.9486759 | L21: =IFERROR(K21/I21,0) -> 0 | M21: =IFERROR(J21/IF(E21>0,E21,SUM(Ingredientes!$E$118:$E$119)),0) -> 32.477932 | N21: =IFERROR(K21/H21,0) -> 0 | O21: 1.36 | P21: =IFERROR(K21-O21,0) -> 0.58867594
A22: empadinha-veg | B22: Empadinha Veg | C22: Salgados assados | D22: 1 | F22: 1H | G22: Não | J22: =SUM(Ingredientes!$I$120:$I$121) -> 0.42311712 | K22: =IFERROR(J22/D22,0) -> 0.42311712 | L22: =IFERROR(K22/I22,0) -> 0 | M22: =IFERROR(J22/IF(E22>0,E22,SUM(Ingredientes!$E$120:$E$121)),0) -> 14.103904 | N22: =IFERROR(K22/H22,0) -> 0 | O22: 0.1421 | P22: =IFERROR(K22-O22,0) -> 0.28101712
A23: empadinha-de-carne | B23: Empadinha de Carne | C23: Salgados assados | D23: 25 | F23: 40 min | G23: Não | J23: =SUM(Ingredientes!$I$122:$I$123) -> 22.168418 | K23: =IFERROR(J23/D23,0) -> 0.88673673 | L23: =IFERROR(K23/I23,0) -> 0 | M23: =IFERROR(J23/IF(E23>0,E23,SUM(Ingredientes!$E$122:$E$123)),0) -> 29.557891 | N23: =IFERROR(K23/H23,0) -> 0 | O23: 0.899 | P23: =IFERROR(K23-O23,0) -> -0.012263265
A24: empadinha-de-frango | B24: Empadinha de Frango | C24: Salgados assados | D24: 25 | F24: 40 min | G24: Não | J24: =SUM(Ingredientes!$I$124:$I$125) -> 15.889896 | K24: =IFERROR(J24/D24,0) -> 0.63559585 | L24: =IFERROR(K24/I24,0) -> 0 | M24: =IFERROR(J24/IF(E24>0,E24,SUM(Ingredientes!$E$124:$E$125)),0) -> 21.186528 | N24: =IFERROR(K24/H24,0) -> 0 | O24: 0.6267 | P24: =IFERROR(K24-O24,0) -> 0.0088958509
A25: escondidinho-de-carne | B25: Escondidinho de Carne | C25: Outros | D25: 10 | F25: 10 min | G25: Não | J25: =SUM(Ingredientes!$I$126:$I$128) -> 122.04508 | K25: =IFERROR(J25/D25,0) -> 12.204508 | L25: =IFERROR(K25/I25,0) -> 0 | M25: =IFERROR(J25/IF(E25>0,E25,SUM(Ingredientes!$E$126:$E$128)),0) -> 34.870023 | N25: =IFERROR(K25/H25,0) -> 0 | O25: 12.4247 | P25: =IFERROR(K25-O25,0) -> -0.22019212
A26: escondidinho-de-frango | B26: Escondidinho de Carne | C26: Outros | D26: 10 | F26: 10 min | G26: Não | J26: =SUM(Ingredientes!$I$129:$I$131) -> 84.373946 | K26: =IFERROR(J26/D26,0) -> 8.4373946 | L26: =IFERROR(K26/I26,0) -> 0 | M26: =IFERROR(J26/IF(E26>0,E26,SUM(Ingredientes!$E$129:$E$131)),0) -> 24.106842 | N26: =IFERROR(K26/H26,0) -> 0 | O26: 8.3411 | P26: =IFERROR(K26-O26,0) -> 0.096294618
A27: focacciaa | B27: Focaccia de Tomate e Alecrim | C27: Pães | D27: 1 | F27: 1H | G27: Não | J27: =SUM(Ingredientes!$I$132:$I$144) -> 6.7584415 | K27: =IFERROR(J27/D27,0) -> 6.7584415 | L27: =IFERROR(K27/I27,0) -> 0 | M27: =IFERROR(J27/IF(E27>0,E27,SUM(Ingredientes!$E$132:$E$144)),0) -> 11.961843 | N27: =IFERROR(K27/H27,0) -> 0 | O27: 6.7584 | P27: =IFERROR(K27-O27,0) -> 4.1460795e-05
A28: frango-desfiado | B28: Frango Desfiado | C28: Massas e bases | D28: 2 | E28: 2 | F28: MODO DE PREPARO | G28: Não | J28: =SUM(Ingredientes!$I$145:$I$152) -> 45.805887 | K28: =IFERROR(J28/D28,0) -> 22.902943 | L28: =IFERROR(K28/I28,0) -> 0 | M28: =IFERROR(J28/IF(E28>0,E28,SUM(Ingredientes!$E$145:$E$152)),0) -> 22.902943 | N28: =IFERROR(K28/H28,0) -> 0 | O28: 22.2528 | P28: =IFERROR(K28-O28,0) -> 0.65014337
A29: frango-desfiado-com-molho-de-to | B29: Frango Desfiado com Molho de Tomate | C29: Massas e bases | D29: 1 | E29: 1.5692 | F29: MODO DE PREPARO | G29: Não | J29: =SUM(Ingredientes!$I$153:$I$154) -> 54.742973 | K29: =IFERROR(J29/D29,0) -> 54.742973 | L29: =IFERROR(K29/I29,0) -> 0 | M29: =IFERROR(J29/IF(E29>0,E29,SUM(Ingredientes!$E$153:$E$154)),0) -> 34.885912 | N29: =IFERROR(K29/H29,0) -> 0 | O29: 53.353 | P29: =IFERROR(K29-O29,0) -> 1.3899725
A30: frango-com-chuchu-e-molho-branc | B30: Frango com Molho Chuchu e Molho Branco e Arroz com Sementes | C30: Massas e bases | D30: 10 | F30: 10 min | G30: Não | J30: =SUM(Ingredientes!$I$155:$I$160) -> 45.465119 | K30: =IFERROR(J30/D30,0) -> 4.5465119 | L30: =IFERROR(K30/I30,0) -> 0 | M30: =IFERROR(J30/IF(E30>0,E30,SUM(Ingredientes!$E$155:$E$160)),0) -> 16.776797 | N30: =IFERROR(K30/H30,0) -> 0 | O30: 4.5831 | P30: =IFERROR(K30-O30,0) -> -0.03658806
A31: granola-salgada | B31: Granola Salgada | C31: Salgados assados | D31: 4 | F31: MODO DE PREPARO | G31: Não | J31: =SUM(Ingredientes!$I$161:$I$169) -> 39.806375 | K31: =IFERROR(J31/D31,0) -> 9.9515937 | L31: =IFERROR(K31/I31,0) -> 0 | M31: =IFERROR(J31/IF(E31>0,E31,SUM(Ingredientes!$E$161:$E$169)),0) -> 39.806375 | N31: =IFERROR(K31/H31,0) -> 0 | O31: 9.9516 | P31: =IFERROR(K31-O31,0) -> -6.2835661e-06
A32: granola-salgada-30g | B32: Granola Salgada | C32: Salgados assados | D32: 25 | F32: MODO DE PREPARO | G32: Não | J32: =SUM(Ingredientes!$I$170:$I$178) -> 39.806375 | K32: =IFERROR(J32/D32,0) -> 1.592255 | L32: =IFERROR(K32/I32,0) -> 0 | M32: =IFERROR(J32/IF(E32>0,E32,SUM(Ingredientes!$E$170:$E$178)),0) -> 39.806375 | N32: =IFERROR(K32/H32,0) -> 0 | O32: 1.5923 | P32: =IFERROR(K32-O32,0) -> -4.5005371e-05
A33: leite-de-amendoim | B33: Leite de Amendoim | C33: Bebidas | D33: 1 | E33: 1 | F33: MODO DE PREPARO | G33: Não | J33: =SUM(Ingredientes!$I$179:$I$179) -> 3.0612245 | K33: =IFERROR(J33/D33,0) -> 3.0612245 | L33: =IFERROR(K33/I33,0) -> 0 | M33: =IFERROR(J33/IF(E33>0,E33,SUM(Ingredientes!$E$179:$E$179)),0) -> 3.0612245 | N33: =IFERROR(K33/H33,0) -> 0 | O33: 3.0612 | P33: =IFERROR(K33-O33,0) -> 2.4489796e-05
A34: leite-de-arroz | B34: Leite de Arroz Integral | C34: Bebidas | D34: 1 | E34: 1 | F34: MODO DE PREPARO | G34: Não | J34: =SUM(Ingredientes!$I$180:$I$180) -> 1.5306122 | K34: =IFERROR(J34/D34,0) -> 1.5306122 | L34: =IFERROR(K34/I34,0) -> 0 | M34: =IFERROR(J34/IF(E34>0,E34,SUM(Ingredientes!$E$180:$E$180)),0) -> 1.5306122 | N34: =IFERROR(K34/H34,0) -> 0 | O34: 1.5306 | P34: =IFERROR(K34-O34,0) -> 1.2244898e-05
A35: maionese-verde | B35: Maionese Verde | C35: Massas e bases | D35: 1 | E35: 1.8043 | F35: 15 min | G35: Não | J35: =SUM(Ingredientes!$I$181:$I$189) -> 10.933837 | K35: =IFERROR(J35/D35,0) -> 10.933837 | L35: =IFERROR(K35/I35,0) -> 0 | M35: =IFERROR(J35/IF(E35>0,E35,SUM(Ingredientes!$E$181:$E$189)),0) -> 6.0598778 | N35: =IFERROR(K35/H35,0) -> 0 | O35: 10.9338 | P35: =IFERROR(K35-O35,0) -> 3.7493544e-05
A36: porcao-maionese-verde | B36: Maionese Verde | C36: Massas e bases | D36: 2 | F36: MODO DE PREPARO | G36: Não | J36: =SUM(Ingredientes!$I$190:$I$190) -> 0.26719038 | K36: =IFERROR(J36/D36,0) -> 0.13359519 | L36: =IFERROR(K36/I36,0) -> 0 | M36: =IFERROR(J36/IF(E36>0,E36,SUM(Ingredientes!$E$190:$E$190)),0) -> 5.3438076 | N36: =IFERROR(K36/H36,0) -> 0 | O36: 0.1336 | P36: =IFERROR(K36-O36,0) -> -4.8106622e-06
A37: manteiga-vegana | B37: Manteiga Vegana | C37: Massas e bases | D37: 1 | E37: 1 | F37: 10 min | G37: Não | J37: =SUM(Ingredientes!$I$191:$I$193) -> 25.283136 | K37: =IFERROR(J37/D37,0) -> 25.283136 | L37: =IFERROR(K37/I37,0) -> 0 | M37: =IFERROR(J37/IF(E37>0,E37,SUM(Ingredientes!$E$191:$E$193)),0) -> 25.283136 | N37: =IFERROR(K37/H37,0) -> 0 | O37: 25.2831 | P37: =IFERROR(K37-O37,0) -> 3.641246e-05
A38: massa-base-para-pao | B38: Massa Base para Pao | C38: Pães | D38: 1 | F38: 1H | G38: Não | J38: =SUM(Ingredientes!$I$194:$I$204) -> 9.3056069 | K38: =IFERROR(J38/D38,0) -> 9.3056069 | L38: =IFERROR(K38/I38,0) -> 0 | M38: =IFERROR(J38/IF(E38>0,E38,SUM(Ingredientes!$E$194:$E$204)),0) -> 10.845696 | N38: =IFERROR(K38/H38,0) -> 0 | O38: 9.3056 | P38: =IFERROR(K38-O38,0) -> 6.8743287e-06
A39: massa-de-quiche | B39: Massa Low Carb para Quiche | C39: Salgados assados | D39: 20 | F39: 1H | G39: Não | J39: =SUM(Ingredientes!$I$205:$I$210) -> 14.050145 | K39: =IFERROR(J39/D39,0) -> 0.70250723 | L39: =IFERROR(K39/I39,0) -> 0 | M39: =IFERROR(J39/IF(E39>0,E39,SUM(Ingredientes!$E$205:$E$210)),0) -> 14.050145 | N39: =IFERROR(K39/H39,0) -> 0 | O39: 0.7025 | P39: =IFERROR(K39-O39,0) -> 7.2287863e-06
A40: creme-para-quiche | B40: Massa Low Carb para Quiche | C40: Salgados assados | D40: 1 | E40: 1 | F40: 1H | G40: Não | J40: =SUM(Ingredientes!$I$211:$I$215) -> 14.666824 | K40: =IFERROR(J40/D40,0) -> 14.666824 | L40: =IFERROR(K40/I40,0) -> 0 | M40: =IFERROR(J40/IF(E40>0,E40,SUM(Ingredientes!$E$211:$E$215)),0) -> 14.666824 | N40: =IFERROR(K40/H40,0) -> 0 | O40: 14.6668 | P40: =IFERROR(K40-O40,0) -> 2.4489796e-05
...

Sheet Ingredientes
A1: Ingredientes das receitas
A2: Uma linha por ingrediente de cada receita. É daqui que sai o custo de cada produto.
A3: Código do produto | B3: Produto | C3: Código do insumo | D3: Insumo | E3: Quantidade (kg) | F3: Fator de correção | G3: Peso bruto | H3: Preço por quilo | I3: Custo
A4: caldo-de-batata-doce | B4: Caldo de Batata Doce | C4: caldo-de-frango | D4: Caldo de Frango | E4: 2 | F4: =IFERROR(INDEX(Insumos!$F$4:$F$168,MATCH($C4,Insumos!$A$4:$A$168,0)),1) -> 0.98 | G4: =IFERROR(E4/F4,0) -> 2.0408163 | H4: =IFERROR(INDEX(Insumos!$G$20:$G$168,MATCH($C4,Insumos!$A$20:$A$168,0)),0) -> 10 | I4: =G4*H4 -> 20.408163
A5: caldo-de-batata-doce | B5: Caldo de Batata Doce | C5: batata-doce-crua-sem-casca | D5: Batata Doce Crua sem Casca | E5: 1 | F5: =IFERROR(INDEX(Insumos!$F$4:$F$168,MATCH($C5,Insumos!$A$4:$A$168,0)),1) -> 0.86142797 | G5: =IFERROR(E5/F5,0) -> 1.1608632 | H5: =IFERROR(INDEX(Insumos!$G$20:$G$168,MATCH($C5,Insumos!$A$20:$A$168,0)),0) -> 5.69 | I5: =G5*H5 -> 6.6053114
A6: caldo-de-batata-doce | B6: Caldo de Batata Doce | C6: sal-integral | D6: Sal Integral | E6: 0.02 | F6: =IFERROR(INDEX(Insumos!$F$4:$F$168,MATCH($C6,Insumos!$A$4:$A$168,0)),1) -> 0.98 | G6: =IFERROR(E6/F6,0) -> 0.020408163 | H6: =IFERROR(INDEX(Insumos!$G$20:$G$168,MATCH($C6,Insumos!$A$20:$A$168,0)),0) -> 5 | I6: =G6*H6 -> 0.10204082
A7: caldo-de-batata-doce | B7: Caldo de Batata Doce | C7: pimenta-do-reino | D7: Pimenta-do-reino | E7: 0.005 | F7: =IFERROR(INDEX(Insumos!$F$4:$F$168,MATCH($C7,Insumos!$A$4:$A$168,0)),1) -> 0.95 | G7: =IFERROR(E7/F7,0) -> 0.0052631579 | H7: =IFERROR(INDEX(Insumos!$G$20:$G$168,MATCH($C7,Insumos!$A$20:$A$168,0)),0) -> 25.16 | I7: =G7*H7 -> 0.13242105
A8: caldo-de-batata-doce | B8: Caldo de Batata Doce | C8: curry | D8: Curry | E8: 0.01 | F8: =IFERROR(INDEX(Insumos!$F$4:$F$168,MATCH($C8,Insumos!$A$4:$A$168,0)),1) -> 0.98 | G8: =IFERROR(E8/F8,0) -> 0.010204082 | H8: =IFERROR(INDEX(Insumos!$G$20:$G$168,MATCH($C8,Insumos!$A$20:$A$168,0)),0) -> 9.54 | I8: =G8*H8 -> 0.097346939
A9: caldo-de-batata-doce | B9: Caldo de Batata Doce | C9: noz-moscada | D9: Noz-moscada | E9: 0.005 | F9: =IFERROR(INDEX(Insumos!$F$4:$F$168,MATCH($C9,Insumos!$A$4:$A$168,0)),1) -> 0.98 | G9: =IFERROR(E9/F9,0) -> 0.0051020408 | H9: =IFERROR(INDEX(Insumos!$G$20:$G$168,MATCH($C9,Insumos!$A$20:$A$168,0)),0) -> 105 | I9: =G9*H9 -> 0.53571429
A10: caldo-de-batata-doce | B10: Caldo de Batata Doce | C10: frango-desfiado | D10: Frango Desfiado | E10: 0.45 | F10: =IFERROR(INDEX(Insumos!$F$4:$F$168,MATCH($C10,Insumos!$A$4:$A$168,0)),1) -> 0.5 | G10: =IFERROR(E10/F10,0) -> 0.9 | H10: =Insumos!$G$6 -> 22.902943 | I10: =G10*H10 -> 20.612649
A11: caldo-de-cabotia | B11: Caldo de Cabotia | C11: caldo-de-frango | D11: Caldo de Frango | E11: 2 | F11: =IFERROR(INDEX(Insumos!$F$4:$F$168,MATCH($C11,Insumos!$A$4:$A$168,0)),1) -> 0.98 | G11: =IFERROR(E11/F11,0) -> 2.0408163 | H11: =IFERROR(INDEX(Insumos!$G$20:$G$168,MATCH($C11,Insumos!$A$20:$A$168,0)),0) -> 10 | I11: =G11*H11 -> 20.408163
A12: caldo-de-cabotia | B12: Caldo de Cabotia | C12: abobora-cabotia | D12: Abobora Cabotia | E12: 1 | F12: =IFERROR(INDEX(Insumos!$F$4:$F$168,MATCH($C12,Insumos!$A$4:$A$168,0)),1) -> 0.97 | G12: =IFERROR(E12/F12,0) -> 1.0309278 | H12: =IFERROR(INDEX(Insumos!$G$20:$G$168,MATCH($C12,Insumos!$A$20:$A$168,0)),0) -> 6 | I12: =G12*H12 -> 6.185567
A13: caldo-de-cabotia | B13: Caldo de Cabotia | C13: sal-integral | D13: Sal Integral | E13: 0.02 | F13: =IFERROR(INDEX(Insumos!$F$4:$F$168,MATCH($C13,Insumos!$A$4:$A$168,0)),1) -> 0.98 | G13: =IFERROR(E13/F13,0) -> 0.020408163 | H13: =IFERROR(INDEX(Insumos!$G$20:$G$168,MATCH($C13,Insumos!$A$20:$A$168,0)),0) -> 5 | I13: =G13*H13 -> 0.10204082
A14: caldo-de-cabotia | B14: Caldo de Cabotia | C14: pimenta-do-reino | D14: Pimenta-do-reino | E14: 0.005 | F14: =IFERROR(INDEX(Insumos!$F$4:$F$168,MATCH($C14,Insumos!$A$4:$A$168,0)),1) -> 0.95 | G14: =IFERROR(E14/F14,0) -> 0.0052631579 | H14: =IFERROR(INDEX(Insumos!$G$20:$G$168,MATCH($C14,Insumos!$A$20:$A$168,0)),0) -> 25.16 | I14: =G14*H14 -> 0.13242105
A15: caldo-de-cabotia | B15: Caldo de Cabotia | C15: curry | D15: Curry | E15: 0.01 | F15: =IFERROR(INDEX(Insumos!$F$4:$F$168,MATCH($C15,Insumos!$A$4:$A$168,0)),1) -> 0.98 | G15: =IFERROR(E15/F15,0) -> 0.010204082 | H15: =IFERROR(INDEX(Insumos!$G$20:$G$168,MATCH($C15,Insumos!$A$20:$A$168,0)),0) -> 9.54 | I15: =G15*H15 -> 0.097346939
A16: caldo-de-cabotia | B16: Caldo de Cabotia | C16: noz-moscada | D16: Noz-moscada | E16: 0.005 | F16: =IFERROR(INDEX(Insumos!$F$4:$F$168,MATCH($C16,Insumos!$A$4:$A$168,0)),1) -> 0.98 | G16: =IFERROR(E16/F16,0) -> 0.0051020408 | H16: =IFERROR(INDEX(Insumos!$G$20:$G$168,MATCH($C16,Insumos!$A$20:$A$168,0)),0) -> 105 | I16: =G16*H16 -> 0.53571429
A17: caldo-de-cabotia | B17: Caldo de Cabotia | C17: frango-desfiado | D17: Frango Desfiado | E17: 0.45 | F17: =IFERROR(INDEX(Insumos!$F$4:$F$168,MATCH($C17,Insumos!$A$4:$A$168,0)),1) -> 0.5 | G17: =IFERROR(E17/F17,0) -> 0.9 | H17: =Insumos!$G$6 -> 22.902943 | I17: =G17*H17 -> 20.612649
A18: caldo-de-legumes-e-frango | B18: Caldo de Legumes e Frango | C18: caldo-de-frango | D18: Caldo de Frango | E18: 2 | F18: =IFERROR(INDEX(Insumos!$F$4:$F$168,MATCH($C18,Insumos!$A$4:$A$168,0)),1) -> 0.98 | G18: =IFERROR(E18/F18,0) -> 2.0408163 | H18: =IFERROR(INDEX(Insumos!$G$20:$G$168,MATCH($C18,Insumos!$A$20:$A$168,0)),0) -> 10 | I18: =G18*H18 -> 20.408163
A19: caldo-de-legumes-e-frango | B19: Caldo de Legumes e Frango | C19: batata-monalisa-in-natura | D19: Batata Monalisa In Natura | E19: 0.25 | F19: =IFERROR(INDEX(Insumos!$F$4:$F$168,MATCH($C19,Insumos!$A$4:$A$168,0)),1) -> 0.8 | G19: =IFERROR(E19/F19,0) -> 0.3125 | H19: =IFERROR(INDEX(Insumos!$G$20:$G$168,MATCH($C19,Insumos!$A$20:$A$168,0)),0) -> 6 | I19: =G19*H19 -> 1.875
A20: caldo-de-legumes-e-frango | B20: Caldo de Legumes e Frango | C20: sal-integral | D20: Sal Integral | E20: 0.02 | F20: =IFERROR(INDEX(Insumos!$F$4:$F$168,MATCH($C20,Insumos!$A$4:$A$168,0)),1) -> 0.98 | G20: =IFERROR(E20/F20,0) -> 0.020408163 | H20: =IFERROR(INDEX(Insumos!$G$20:$G$168,MATCH($C20,Insumos!$A$20:$A$168,0)),0) -> 5 | I20: =G20*H20 -> 0.10204082
A21: caldo-de-legumes-e-frango | B21: Caldo de Legumes e Frango | C21: pimenta-do-reino | D21: Pimenta-do-reino | E21: 0.005 | F21: =IFERROR(INDEX(Insumos!$F$4:$F$168,MATCH($C21,Insumos!$A$4:$A$168,0)),1) -> 0.95 | G21: =IFERROR(E21/F21,0) -> 0.0052631579 | H21: =IFERROR(INDEX(Insumos!$G$20:$G$168,MATCH($C21,Insumos!$A$20:$A$168,0)),0) -> 25.16 | I21: =G21*H21 -> 0.13242105
A22: caldo-de-legumes-e-frango | B22: Caldo de Legumes e Frango | C22: curry | D22: Curry | E22: 0.01 | F22: =IFERROR(INDEX(Insumos!$F$4:$F$168,MATCH($C22,Insumos!$A$4:$A$168,0)),1) -> 0.98 | G22: =IFERROR(E22/F22,0) -> 0.010204082 | H22: =IFERROR(INDEX(Insumos!$G$20:$G$168,MATCH($C22,Insumos!$A$20:$A$168,0)),0) -> 9.54 | I22: =G22*H22 -> 0.097346939
A23: caldo-de-legumes-e-frango | B23: Caldo de Legumes e Frango | C23: noz-moscada | D23: Noz-moscada | E23: 0.005 | F23: =IFERROR(INDEX(Insumos!$F$4:$F$168,MATCH($C23,Insumos!$A$4:$A$168,0)),1) -> 0.98 | G23: =IFERROR(E23/F23,0) -> 0.0051020408 | H23: =IFERROR(INDEX(Insumos!$G$20:$G$168,MATCH($C23,Insumos!$A$20:$A$168,0)),0) -> 105 | I23: =G23*H23 -> 0.53571429
A24: caldo-de-legumes-e-frango | B24: Caldo de Legumes e Frango | C24: frango-desfiado | D24: Frango Desfiado | E24: 0.45 | F24: =IFERROR(INDEX(Insumos!$F$4:$F$168,MATCH($C24,Insumos!$A$4:$A$168,0)),1) -> 0.5 | G24: =IFERROR(E24/F24,0) -> 0.9 | H24: =Insumos!$G$6 -> 22.902943 | I24: =G24*H24 -> 20.612649
A25: caldo-de-legumes-e-frango | B25: Caldo de Legumes e Frango | C25: brocolis | D25: Brócolis | E25: 0.25 | F25: =IFERROR(INDEX(Insumos!$F$4:$F$168,MATCH($C25,Insumos!$A$4:$A$168,0)),1) -> 0.95 | G25: =IFERROR(E25/F25,0) -> 0.26315789 | H25: =IFERROR(INDEX(Insumos!$G$20:$G$168,MATCH($C25,Insumos!$A$20:$A$168,0)),0) -> 30 | I25: =G25*H25 -> 7.8947368
A26: caldo-de-legumes-e-frango | B26: Caldo de Legumes e Frango | C26: cenoura-com-casca | D26: Cenoura com Casca | E26: 0.25 | F26: =IFERROR(INDEX(Insumos!$F$4:$F$168,MATCH($C26,Insumos!$A$4:$A$168,0)),1) -> 0.98 | G26: =IFERROR(E26/F26,0) -> 0.25510204 | H26: =IFERROR(INDEX(Insumos!$G$20:$G$168,MATCH($C26,Insumos!$A$20:$A$168,0)),0) -> 7.9 | I26: =G26*H26 -> 2.0153061
A27: caldo-de-legumes-e-frango | B27: Caldo de Legumes e Frango | C27: chuchu | D27: Chuchu | E27: 0.25 | F27: =IFERROR(INDEX(Insumos!$F$4:$F$168,MATCH($C27,Insumos!$A$4:$A$168,0)),1) -> 0.95 | G27: =IFERROR(E27/F27,0) -> 0.26315789 | H27: =IFERROR(INDEX(Insumos!$G$20:$G$168,MATCH($C27,Insumos!$A$20:$A$168,0)),0) -> 7 | I27: =G27*H27 -> 1.8421053
A28: coxinha-de-batata-doce | B28: Coxinha Massa Trad | C28: frango-desfiado-com-molho-de-tomate | D28: Frango Desfiado com Molho de Tomate | E28: 0.75 | F28: =IFERROR(INDEX(Insumos!$F$4:$F$168,MATCH($C28,Insumos!$A$4:$A$168,0)),1) -> 1 | G28: =IFERROR(E28/F28,0) -> 0.75 | H28: =Insumos!$G$7 -> 34.885912 | I28: =G28*H28 -> 26.164434
A29: coxinha-de-batata-doce | B29: Coxinha Massa Trad | C29: linhaca-dourada | D29: Linhaça Dourada | E29: 0.5 | F29: =IFERROR(INDEX(Insumos!$F$4:$F$168,MATCH($C29,Insumos!$A$4:$A$168,0)),1) -> 0.98 | G29: =IFERROR(E29/F29,0) -> 0.51020408 | H29: =IFERROR(INDEX(Insumos!$G$20:$G$168,MATCH($C29,Insumos!$A$20:$A$168,0)),0) -> 28.75 | I29: =G29*H29 -> 14.668367
A30: coxinha-de-batata-doce | B30: Coxinha Massa Trad | C30: batata-doce-cozida-no-vapor | D30: Batata Doce Cozida No Vapor | E30: 2.039 | F30: =IFERROR(INDEX(Insumos!$F$4:$F$168,MATCH($C30,Insumos!$A$4:$A$168,0)),1) -> 0.94016675 | G30: =IFERROR(E30/F30,0) -> 2.1687642 | H30: =IFERROR(INDEX(Insumos!$G$20:$G$168,MATCH($C30,Insumos!$A$20:$A$168,0)),0) -> 12 | I30: =G30*H30 -> 26.025171
A31: coxinha-de-batata-doce | B31: Coxinha Massa Trad | C31: ovos | D31: Ovos | E31: 0.1 | F31: =IFERROR(INDEX(Insumos!$F$4:$F$168,MATCH($C31,Insumos!$A$4:$A$168,0)),1) -> 1 | G31: =IFERROR(E31/F31,0) -> 0.1 | H31: =IFERROR(INDEX(Insumos!$G$20:$G$168,MATCH($C31,Insumos!$A$20:$A$168,0)),0) -> 15 | I31: =G31*H31 -> 1.5
A32: coxinha-de-batata-doce | B32: Coxinha Massa Trad | C32: agua | D32: Água | E32: 0.15 | F32: =IFERROR(INDEX(Insumos!$F$4:$F$168,MATCH($C32,Insumos!$A$4:$A$168,0)),1) -> 0.98 | G32: =IFERROR(E32/F32,0) -> 0.15306122 | H32: =IFERROR(INDEX(Insumos!$G$20:$G$168,MATCH($C32,Insumos!$A$20:$A$168,0)),0) -> 1.5 | I32: =G32*H32 -> 0.22959184
A33: cracker-sem-gluten | B33: Cracker sem Glúten | C33: farinha-de-arroz-integral | D33: Farinha de Arroz Integral | E33: 0.15 | F33: =IFERROR(INDEX(Insumos!$F$4:$F$168,MATCH($C33,Insumos!$A$4:$A$168,0)),1) -> 0.98 | G33: =IFERROR(E33/F33,0) -> 0.15306122 | H33: =IFERROR(INDEX(Insumos!$G$20:$G$168,MATCH($C33,Insumos!$A$20:$A$168,0)),0) -> 9.5 | I33: =G33*H33 -> 1.4540816
A34: cracker-sem-gluten | B34: Cracker sem Glúten | C34: polvilho-doce | D34: Polvilho Doce | E34: 0.065 | F34: =IFERROR(INDEX(Insumos!$F$4:$F$168,MATCH($C34,Insumos!$A$4:$A$168,0)),1) -> 0.98 | G34: =IFERROR(E34/F34,0) -> 0.066326531 | H34: =IFERROR(INDEX(Insumos!$G$20:$G$168,MATCH($C34,Insumos!$A$20:$A$168,0)),0) -> 12 | I34: =G34*H34 -> 0.79591837
A35: cracker-sem-gluten | B35: Cracker sem Glúten | C35: psyllium | D35: Psyllium | E35: 0.015 | F35: =IFERROR(INDEX(Insumos!$F$4:$F$168,MATCH($C35,Insumos!$A$4:$A$168,0)),1) -> 0.98 | G35: =IFERROR(E35/F35,0) -> 0.015306122 | H35: =IFERROR(INDEX(Insumos!$G$20:$G$168,MATCH($C35,Insumos!$A$20:$A$168,0)),0) -> 54.4 | I35: =G35*H35 -> 0.83265306
A36: cracker-sem-gluten | B36: Cracker sem Glúten | C36: acucar-demerara | D36: Açucar Demerara | E36: 0.01 | F36: =IFERROR(INDEX(Insumos!$F$4:$F$168,MATCH($C36,Insumos!$A$4:$A$168,0)),1) -> 0.98 | G36: =IFERROR(E36/F36,0) -> 0.010204082 | H36: =IFERROR(INDEX(Insumos!$G$20:$G$168,MATCH($C36,Insumos!$A$20:$A$168,0)),0) -> 6 | I36: =G36*H36 -> 0.06122449
A37: cracker-sem-gluten | B37: Cracker sem Glúten | C37: sal-integral | D37: Sal Integral | E37: 0.005 | F37: =IFERROR(INDEX(Insumos!$F$4:$F$168,MATCH($C37,Insumos!$A$4:$A$168,0)),1) -> 0.98 | G37: =IFERROR(E37/F37,0) -> 0.0051020408 | H37: =IFERROR(INDEX(Insumos!$G$20:$G$168,MATCH($C37,Insumos!$A$20:$A$168,0)),0) -> 5 | I37: =G37*H37 -> 0.025510204
A38: cracker-sem-gluten | B38: Cracker sem Glúten | C38: goma-xantana | D38: Goma Xantana | E38: 0.0005 | F38: =IFERROR(INDEX(Insumos!$F$4:$F$168,MATCH($C38,Insumos!$A$4:$A$168,0)),1) -> 0.98 | G38: =IFERROR(E38/F38,0) -> 0.00051020408 | H38: =IFERROR(INDEX(Insumos!$G$20:$G$168,MATCH($C38,Insumos!$A$20:$A$168,0)),0) -> 36.86 | I38: =G38*H38 -> 0.018806122
A39: cracker-sem-gluten | B39: Cracker sem Glúten | C39: fermento-biologico-seco | D39: Fermento Biologico Seco | E39: 0.01 | F39: =IFERROR(INDEX(Insumos!$F$4:$F$168,MATCH($C39,Insumos!$A$4:$A$168,0)),1) -> 0.98 | G39: =IFERROR(E39/F39,0) -> 0.010204082 | H39: =IFERROR(INDEX(Insumos!$G$20:$G$168,MATCH($C39,Insumos!$A$20:$A$168,0)),0) -> 14.9 | I39: =G39*H39 -> 0.15204082
A40: cracker-sem-gluten | B40: Cracker sem Glúten | C40: azeite-de-oliva | D40: Azeite de Oliva | E40: 0.03 | F40: =IFERROR(INDEX(Insumos!$F$4:$F$168,MATCH($C40,Insumos!$A$4:$A$168,0)),1) -> 0.95 | G40: =IFERROR(E40/F40,0) -> 0.031578947 | H40: =IFERROR(INDEX(Insumos!$G$20:$G$168,MATCH($C40,Insumos!$A$20:$A$168,0)),0) -> 20 | I40: =G40*H40 -> 0.63157895
...

Sheet Conferência
A1: Conferência
A2: Compara o que esta planilha calcula com o que a sua planilha antiga calculava. Serve para você conferir se a migração ficou certa.
A3: O que foi conferido | B3: Valor | C3: O que isso quer dizer
A4: Receitas na planilha | B4: =COUNTA(Produtos!$A$4:$A$76) -> 73 | C4: Cada receita sua virou uma linha na aba Produtos.
A5: Receitas que a planilha antiga também calculava | B5: =COUNTIF(Produtos!$O$4:$O$76,">0") -> 73 | C5: Só estas dá para comparar. As outras a planilha antiga não trazia o custo por porção.
A6: Receitas com o mesmo custo (diferença abaixo de 1 centavo) | B6: =SUMPRODUCT((Produtos!$O$4:$O$76>0)*(ABS(Produtos!$P$4:$P$76)<0.01)) -> 45 | C6: Estas bateram exatamente com a sua planilha.
A7: Receitas com custo diferente | B7: =SUMPRODUCT((Produtos!$O$4:$O$76>0)*(ABS(Produtos!$P$4:$P$76)>=0.01)) -> 28 | C7: Veja a lista abaixo. Em geral é o alho-poró, explicado no documento que acompanha.
A8: Maior diferença para cima | B8: =MAX(Produtos!$P$4:$P$76) -> 7.3351373 | C8: Quanto o maior custo subiu em relação à planilha antiga.
A9: Maior diferença para baixo | B9: =MIN(Produtos!$P$4:$P$76) -> -0.22019212 | C9: Quanto o maior custo caiu em relação à planilha antiga.
A10: Insumos cadastrados | B10: =COUNTA(Insumos!$A$4:$A$168) -> 165 | C10: Tudo que entra em alguma receita.
A11: Insumos sem preço | B11: =COUNTIF(Insumos!$G$20:$G$168,0) -> 0 | C11: Se aparecer algum, o custo das receitas que o usam está baixo demais.
A12: Insumos sem data de cotação | B12: =COUNTBLANK(Insumos!$I$20:$I$168) -> 149 | C12: Preencher ajuda a saber quando o preço envelheceu.
A15: Receitas em que o custo mudou
A16: Produto | B16: Custo agora | C16: Custo antes
A17: =IF(ABS(Produtos!$P$4)<0.01,"",Produtos!$B$4) -> Caldo de Batata Doce | B17: =IF(ABS(Produtos!$P$4)<0.01,"",Produtos!$K$4) -> 5.388183 | C17: =IF(ABS(Produtos!$P$4)<0.01,"",Produtos!$O$4) -> 5.3232
A18: =IF(ABS(Produtos!$P$5)<0.01,"",Produtos!$B$5) -> Caldo de Cabotia | B18: =IF(ABS(Produtos!$P$5)<0.01,"",Produtos!$K$5) -> 5.3415447 | C18: =IF(ABS(Produtos!$P$5)<0.01,"",Produtos!$O$5) -> 5.2765
A19: =IF(ABS(Produtos!$P$6)<0.01,"",Produtos!$B$6) -> Caldo de Legumes e Frango | B19: =IF(ABS(Produtos!$P$6)<0.01,"",Produtos!$K$6) -> 6.1683871 | C19: =IF(ABS(Produtos!$P$6)<0.01,"",Produtos!$O$6) -> 6.1034
A20: =IF(ABS(Produtos!$P$7)<0.01,"",Produtos!$B$7) -> Coxinha Massa Trad | B20: =IF(ABS(Produtos!$P$7)<0.01,"",Produtos!$K$7) -> 3.6098718 | C20: =IF(ABS(Produtos!$P$7)<0.01,"",Produtos!$O$7) -> 3.5749
A21: =IF(ABS(Produtos!$P$8)<0.01,"",Produtos!$B$8) | B21: =IF(ABS(Produtos!$P$8)<0.01,"",Produtos!$K$8) | C21: =IF(ABS(Produtos!$P$8)<0.01,"",Produtos!$O$8)
A22: =IF(ABS(Produtos!$P$9)<0.01,"",Produtos!$B$9) -> Esfira de Carne | B22: =IF(ABS(Produtos!$P$9)<0.01,"",Produtos!$K$9) -> 6.06824 | C22: =IF(ABS(Produtos!$P$9)<0.01,"",Produtos!$O$9) -> 6.1932
A23: =IF(ABS(Produtos!$P$10)<0.01,"",Produtos!$B$10) | B23: =IF(ABS(Produtos!$P$10)<0.01,"",Produtos!$K$10) | C23: =IF(ABS(Produtos!$P$10)<0.01,"",Produtos!$O$10)
A24: =IF(ABS(Produtos!$P$11)<0.01,"",Produtos!$B$11) | B24: =IF(ABS(Produtos!$P$11)<0.01,"",Produtos!$K$11) | C24: =IF(ABS(Produtos!$P$11)<0.01,"",Produtos!$O$11)
A25: =IF(ABS(Produtos!$P$12)<0.01,"",Produtos!$B$12) -> Quiche de Brócolis | B25: =IF(ABS(Produtos!$P$12)<0.01,"",Produtos!$K$12) -> 4.0620223 | C25: =IF(ABS(Produtos!$P$12)<0.01,"",Produtos!$O$12) -> 3.9601
A26: =IF(ABS(Produtos!$P$13)<0.01,"",Produtos!$B$13) | B26: =IF(ABS(Produtos!$P$13)<0.01,"",Produtos!$K$13) | C26: =IF(ABS(Produtos!$P$13)<0.01,"",Produtos!$O$13)
A27: =IF(ABS(Produtos!$P$14)<0.01,"",Produtos!$B$14) -> Sanduba de Pao-nobis, Frango e Requeiju | B27: =IF(ABS(Produtos!$P$14)<0.01,"",Produtos!$K$14) -> 3.3499976 | C27: =IF(ABS(Produtos!$P$14)<0.01,"",Produtos!$O$14) -> 3.3114
A28: =IF(ABS(Produtos!$P$15)<0.01,"",Produtos!$B$15) -> Torta Salgada de Frango | B28: =IF(ABS(Produtos!$P$15)<0.01,"",Produtos!$K$15) -> 2.9265796 | C28: =IF(ABS(Produtos!$P$15)<0.01,"",Produtos!$O$15) -> 2.8823
A29: =IF(ABS(Produtos!$P$16)<0.01,"",Produtos!$B$16) | B29: =IF(ABS(Produtos!$P$16)<0.01,"",Produtos!$K$16) | C29: =IF(ABS(Produtos!$P$16)<0.01,"",Produtos!$O$16)
A30: =IF(ABS(Produtos!$P$17)<0.01,"",Produtos!$B$17) | B30: =IF(ABS(Produtos!$P$17)<0.01,"",Produtos!$K$17) | C30: =IF(ABS(Produtos!$P$17)<0.01,"",Produtos!$O$17)
A31: =IF(ABS(Produtos!$P$18)<0.01,"",Produtos!$B$18) | B31: =IF(ABS(Produtos!$P$18)<0.01,"",Produtos!$K$18) | C31: =IF(ABS(Produtos!$P$18)<0.01,"",Produtos!$O$18)
A32: =IF(ABS(Produtos!$P$19)<0.01,"",Produtos!$B$19) -> Croquete de Batata e Frango | B32: =IF(ABS(Produtos!$P$19)<0.01,"",Produtos!$K$19) -> 3.1517018 | C32: =IF(ABS(Produtos!$P$19)<0.01,"",Produtos!$O$19) -> 3.0867
A33: =IF(ABS(Produtos!$P$20)<0.01,"",Produtos!$B$20) | B33: =IF(ABS(Produtos!$P$20)<0.01,"",Produtos!$K$20) | C33: =IF(ABS(Produtos!$P$20)<0.01,"",Produtos!$O$20)
A34: =IF(ABS(Produtos!$P$21)<0.01,"",Produtos!$B$21) -> Empada de Frango | B34: =IF(ABS(Produtos!$P$21)<0.01,"",Produtos!$K$21) -> 1.9486759 | C34: =IF(ABS(Produtos!$P$21)<0.01,"",Produtos!$O$21) -> 1.36
A35: =IF(ABS(Produtos!$P$22)<0.01,"",Produtos!$B$22) -> Empadinha Veg | B35: =IF(ABS(Produtos!$P$22)<0.01,"",Produtos!$K$22) -> 0.42311712 | C35: =IF(ABS(Produtos!$P$22)<0.01,"",Produtos!$O$22) -> 0.1421
A36: =IF(ABS(Produtos!$P$23)<0.01,"",Produtos!$B$23) -> Empadinha de Carne | B36: =IF(ABS(Produtos!$P$23)<0.01,"",Produtos!$K$23) -> 0.88673673 | C36: =IF(ABS(Produtos!$P$23)<0.01,"",Produtos!$O$23) -> 0.899
A37: =IF(ABS(Produtos!$P$24)<0.01,"",Produtos!$B$24) | B37: =IF(ABS(Produtos!$P$24)<0.01,"",Produtos!$K$24) | C37: =IF(ABS(Produtos!$P$24)<0.01,"",Produtos!$O$24)
A38: =IF(ABS(Produtos!$P$25)<0.01,"",Produtos!$B$25) -> Escondidinho de Carne | B38: =IF(ABS(Produtos!$P$25)<0.01,"",Produtos!$K$25) -> 12.204508 | C38: =IF(ABS(Produtos!$P$25)<0.01,"",Produtos!$O$25) -> 12.4247
A39: =IF(ABS(Produtos!$P$26)<0.01,"",Produtos!$B$26) -> Escondidinho de Carne | B39: =IF(ABS(Produtos!$P$26)<0.01,"",Produtos!$K$26) -> 8.4373946 | C39: =IF(ABS(Produtos!$P$26)<0.01,"",Produtos!$O$26) -> 8.3411
A40: =IF(ABS(Produtos!$P$27)<0.01,"",Produtos!$B$27) | B40: =IF(ABS(Produtos!$P$27)<0.01,"",Produtos!$K$27) | C40: =IF(ABS(Produtos!$P$27)<0.01,"",Produtos!$O$27)
A41: =IF(ABS(Produtos!$P$28)<0.01,"",Produtos!$B$28) -> Frango Desfiado | B41: =IF(ABS(Produtos!$P$28)<0.01,"",Produtos!$K$28) -> 22.902943 | C41: =IF(ABS(Produtos!$P$28)<0.01,"",Produtos!$O$28) -> 22.2528
A42: =IF(ABS(Produtos!$P$29)<0.01,"",Produtos!$B$29) -> Frango Desfiado com Molho de Tomate | B42: =IF(ABS(Produtos!$P$29)<0.01,"",Produtos!$K$29) -> 54.742973 | C42: =IF(ABS(Produtos!$P$29)<0.01,"",Produtos!$O$29) -> 53.353
...

Sheet Pendências
A1: Para você conferir
A2: Coisas que a planilha antiga deixava em aberto e que ninguém consegue adivinhar por você. Nada aqui impede de usar a planilha; é a lista do que vale olhar com calma.
A3: # | B3: O que encontramos
A4: 1 | B4: Pão-para Sanduiche: comprado por unidade. Falta saber quanto pesa uma unidade para o custo por quilo fechar.
A5: 2 | B5: Massa de Pizza Vegana: comprado por unidade. Falta saber quanto pesa uma unidade para o custo por quilo fechar.
A6: 3 | B6: Pão Funcional Levissima P 1 Sanduiche: comprado por unidade. Falta saber quanto pesa uma unidade para o custo por quilo fechar.
A7: 4 | B7: Probiotico: comprado por unidade. Falta saber quanto pesa uma unidade para o custo por quilo fechar.
A8: 5 | B8: A aba se chama 'PATINHO ACEBOLADO DE VEGETAIS A' mas por dentro está escrito 'PATINHO ACEBOLADO COM VEGETAIS ASSADOS'. Usamos o nome de dentro. Confirmar qual é o certo.
A9: 6 | B9: Frango com Chuchu e Molho Branc: o ingrediente 'ARROZ INTEGRAL COZIDO' não existe na lista de insumos e ficou de fora do custo.
A10: 7 | B10: A aba se chama 'FRANGO COM CHUCHU E MOLHO BRANC' mas por dentro está escrito 'FRANGO COM MOLHO CHUCHU E MOLHO BRANCO E ARROZ COM SEMENTES'. Usamos o nome de dentro. Confirmar qual é o certo.
A11: 8 | B11: A aba se chama 'SANDUBA DE FRANGO' mas por dentro está escrito 'SANDUBA DE PAO-NOBIS, FRANGO E REQUEIJU'. Usamos o nome de dentro. Confirmar qual é o certo.
A12: 9 | B12: A aba se chama 'ESCONDIDINHO DE FRANGO' mas por dentro está escrito 'ESCONDIDINHO DE CARNE'. Usamos o nome de dentro. Confirmar qual é o certo.
A13: 10 | B13: A aba se chama 'COXINHA de batata doce' mas por dentro está escrito 'COXINHA MASSA TRAD'. Usamos o nome de dentro. Confirmar qual é o certo.
A14: 11 | B14: A aba se chama 'CREME DE CASTANHA' mas por dentro está escrito 'CATUPIRY DE CASTANHA'. Usamos o nome de dentro. Confirmar qual é o certo.
A15: 12 | B15: A aba se chama 'PÃO CASEIRO' mas por dentro está escrito 'PÃO ROBERTA'. Usamos o nome de dentro. Confirmar qual é o certo.
... A49: 46 | B49: A aba se chama 'FRANGO DESFIADO COM MOLHO DE TO' mas por dentro está escrito 'FRANGO DESFIADO COM MOLHO DE TOMATE'. Usamos o nome de dentro. Confirmar qual é o certo.

Sheet Listas
A1: Listas
A2: Alimentam as caixinhas de escolha das outras abas.
A3: Categorias | B3: Unidades | C3: Fornecedores | D3: Vende?
A4: Bebidas | B4: kg | C4: Ademir | D4: Sim
A5: Caldos | B5: L | C5: Ares | D5: Não
A6: Massas e bases | B6: un | C6: Ares da Natureza
A7: Outros | C7: Argentina
A8: Pães | C8: Cacau Show
A9: Salgados assados | C9: Cantina
A10: Salgados fritos | C10: Cantina da Fruta
A11: Sanduíches | C11: Cedro
C12: Cipra
C13: Cometa
C14: Equi
C15: Equilibrium
C16: Farmacia
C17: Feirinha
C18: Fruteira
C19: Ingredientes Online
C20: Marcon Atacado Beltrao
C21: Marcon Atadaco Beltrao
C22: Melo
C23: Mercado Livre
... C29: cozinha
